<?xml version="1.0"?>
<robot xmlns:xacro="http://www.ros.org/wiki/xacro" name="rover_robot">

    <material name="rover_body">
        <color rgba="0.85 0.55 0.1 1"/>
    </material>
    <material name="rover_wheels">
        <color rgba="0.2 0.2 0.2 1"/>
    </material>
    
    <xacro:property name="wheel_radius" value="0.1"/>
    <xacro:property name="wheel_length" value="0.05"/>
    <xacro:property name="wheel_mass" value="1.0"/>

    <link name="base_link"></link>

    <joint name="chassis_joint" type="fixed">
        <parent link="base_link"/>
        <child link="chassis"/>
        <origin xyz="0 0 0.1"/> </joint>

    <link name="chassis">
        <visual>
            <geometry>
                <box size="0.5 0.3 0.1"/>
            </geometry>
            <material name="rover_body"/>
        </visual>
        <collision>
            <geometry>
                <box size="0.5 0.3 0.1"/>
            </geometry>
        </collision>
        <inertial>
            <mass value="10.0"/>
            <origin xyz="0 0 0"/>
            <inertia ixx="0.083" ixy="0.0" ixz="0.0" iyy="0.216" iyz="0.0" izz="0.283"/>
        </inertial>
    </link>
    
    <joint name="camera_arm_joint" type="revolute">
        <parent link="chassis"/>
        <child link="camera_arm"/>
        <origin xyz="0.15 0 0.05" rpy="0 0 0"/>
        <axis xyz="0 1 0"/> 
        <limit lower="-0.785" upper="0.785" effort="10.0" velocity="1.0"/> 
    </joint>

    <link name="camera_arm">
        <visual>
            <origin xyz="0 0 0.05" rpy="0 0 0"/>
            <geometry>
                <box size="0.04 0.04 0.1"/>
            </geometry>
            <material name="rover_body"/> 
        </visual>
        <collision>
            <origin xyz="0 0 0.05" rpy="0 0 0"/>
            <geometry>
                <box size="0.04 0.04 0.1"/>
            </geometry>
        </collision>
        <inertial>
            <origin xyz="0 0 0.05" rpy="0 0 0"/>
            <mass value="0.1"/>
            <inertia ixx="0.0001" ixy="0.0" ixz="0.0" iyy="0.0001" iyz="0.0" izz="0.0001"/>
        </inertial>
    </link>
    
    <joint name="camera_joint" type="fixed">
        <parent link="camera_arm"/>
        <child link="camera_link"/>
        <origin xyz="0.02 0 0.08" rpy="0 0 0"/> 
    </joint>

    <link name="camera_link">
        <visual>
            <geometry><box size="0.02 0.04 0.04"/></geometry>
            <material name="rover_wheels"/> </visual>
    </link>

    <joint name="camera_optical_joint" type="fixed">
        <parent link="camera_link"/>
        <child link="camera_link_optical"/>
        <origin xyz="0 0 0" rpy="-1.5708 0 -1.5708"/>
    </joint>
    <link name="camera_link_optical"></link>

    <joint name="lidar_joint" type="fixed">
        <parent link="chassis"/>
        <child link="lidar_link"/>
        <origin xyz="-0.1 0 0.075" rpy="0 0 0"/>
    </joint>

    <link name="lidar_link">
        <visual>
            <geometry><cylinder radius="0.04" length="0.05"/></geometry>
            <material name="rover_body"/>
        </visual>
    </link>

    <joint name="imu_joint" type="fixed">
        <parent link="chassis"/>
        <child link="imu_link"/>
        <origin xyz="0 0 0" rpy="0 0 0"/>
    </joint>
    <link name="imu_link"></link>

    <xacro:macro name="rover_wheel" params="prefix x_reflect y_reflect">
        <joint name="${prefix}_wheel_joint" type="continuous">
            <parent link="chassis"/>
            <child link="${prefix}_wheel"/>
            <origin xyz="${x_reflect * 0.15} ${y_reflect * 0.175} 0" rpy="${-1.5708 * y_reflect} 0 0"/>
            <axis xyz="0 0 ${y_reflect}"/>
        </joint>

        <link name="${prefix}_wheel">
            <visual>
                <geometry>
                    <cylinder radius="${wheel_radius}" length="${wheel_length}"/>
                </geometry>
                <material name="rover_wheels"/>
            </visual>
            <collision>
                <geometry>
                    <cylinder radius="${wheel_radius}" length="${wheel_length}"/>
                </geometry>
            </collision>
            <inertial>
                <mass value="${wheel_mass}"/>
                <inertia ixx="0.0027" ixy="0.0" ixz="0.0" iyy="0.0027" iyz="0.0" izz="0.005"/>
            </inertial>
        </link>
    </xacro:macro>

    <xacro:rover_wheel prefix="front_left" x_reflect="1" y_reflect="1"/>
    <xacro:rover_wheel prefix="front_right" x_reflect="1" y_reflect="-1"/>
    <xacro:rover_wheel prefix="rear_left" x_reflect="-1" y_reflect="1"/>
    <xacro:rover_wheel prefix="rear_right" x_reflect="-1" y_reflect="-1"/>
    
    <ros2_control name="RoverControl" type="system">
        <hardware>
            <plugin>ign_ros2_control/IgnitionSystem</plugin>
        </hardware>
        <joint name="camera_arm_joint">
            <command_interface name="position"/>
            <state_interface name="position"/>
            <state_interface name="velocity"/>
        </joint>
    </ros2_control>

    <gazebo>
        <plugin filename="ignition-gazebo-diff-drive-system" name="ignition::gazebo::systems::DiffDrive">
            <left_joint>front_left_wheel_joint</left_joint>
            <left_joint>rear_left_wheel_joint</left_joint>
            <right_joint>front_right_wheel_joint</right_joint>
            <right_joint>rear_right_wheel_joint</right_joint>
            <wheel_separation>0.35</wheel_separation>
            <wheel_radius>0.1</wheel_radius>
            <odom_publish_frequency>50</odom_publish_frequency>
            <topic>cmd_vel</topic>
            
            <publish_odom>true</publish_odom>
            <publish_odom_tf>true</publish_odom_tf>
            <frame_id>odom</frame_id>
            <child_frame_id>base_link</child_frame_id>
        </plugin>
    </gazebo>
    
    <gazebo reference="camera_link">
        <sensor name="camera" type="camera">
            <ignition_frame_id>camera_link_optical</ignition_frame_id>
            <always_on>true</always_on>
            <update_rate>30</update_rate>
            <visualize>true</visualize>
            <topic>camera/image_raw</topic>
            <camera>
                <horizontal_fov>1.089</horizontal_fov>
                <image>
                    <width>640</width>
                    <height>480</height>
                    <format>R8G8B8</format>
                </image>
                <clip><near>0.05</near><far>8.0</far></clip>
            </camera>
        </sensor>
    </gazebo>

    <gazebo reference="lidar_link">
        <sensor name="lidar" type="gpu_lidar">
            <ignition_frame_id>lidar_link</ignition_frame_id>
            <always_on>true</always_on>
            <update_rate>10</update_rate>
            <visualize>true</visualize>
            <topic>scan</topic>
            <ray>
                <scan>
                    <horizontal>
                        <samples>360</samples>
                        <resolution>1.0</resolution>
                        <min_angle>-3.14159</min_angle>
                        <max_angle>3.14159</max_angle>
                    </horizontal>
                </scan>
                <range>
                    <min>0.12</min><max>3.5</max><resolution>0.015</resolution>
                </range>
            </ray>
        </sensor>
    </gazebo>

    <gazebo reference="imu_link">
        <sensor name="imu_sensor" type="imu">
            <ignition_frame_id>imu_link</ignition_frame_id>
            <always_on>true</always_on>
            <update_rate>100</update_rate>
            <visualize>true</visualize>
            <topic>imu</topic>
        </sensor>
    </gazebo>
    
    <gazebo>
        <plugin filename="ign_ros2_control-system" name="ign_ros2_control::IgnitionROS2ControlPlugin">
            <parameters>$(find rover_robot)/config/controllers.yaml</parameters>
        </plugin>
    </gazebo>

</robot>
