<?xml version="1.0"?>
<robot xmlns:xacro="http://www.ros.org/wiki/xacro" name="rover_robot">

    <material name="rover_body">
        <color rgba="0.85 0.55 0.1 1"/>
    </material>
    <material name="rover_wheels">
        <color rgba="0.2 0.2 0.2 1"/>
    </material>
    
    <xacro:property name="wheel_radius" value="0.1"/>
    <xacro:property name="wheel_length" value="0.05"/>
    <xacro:property name="wheel_mass" value="1.0"/>

    <link name="base_link"></link>

    <joint name="chassis_joint" type="fixed">
        <parent link="base_link"/>
        <child link="chassis"/>
        <origin xyz="0 0 0.1"/> </joint>

    <link name="chassis">
        <visual>
            <geometry>
                <box size="0.5 0.3 0.1"/>
            </geometry>
            <material name="rover_body"/>
        </visual>
        <collision>
            <geometry>
                <box size="0.5 0.3 0.1"/>
            </geometry>
        </collision>
        <inertial>
            <mass value="10.0"/>
            <origin xyz="0 0 0"/>
            <inertia ixx="0.083" ixy="0.0" ixz="0.0" iyy="0.216" iyz="0.0" izz="0.283"/>
        </inertial>
    </link>

    <xacro:macro name="rover_wheel" params="prefix x_reflect y_reflect">
        <joint name="${prefix}_wheel_joint" type="continuous">
            <parent link="chassis"/>
            <child link="${prefix}_wheel"/>
            <origin xyz="${x_reflect * 0.15} ${y_reflect * 0.175} 0" rpy="${-1.5708 * y_reflect} 0 0"/>
            <axis xyz="0 0 ${y_reflect}"/>
        </joint>

        <link name="${prefix}_wheel">
            <visual>
                <geometry>
                    <cylinder radius="${wheel_radius}" length="${wheel_length}"/>
                </geometry>
                <material name="rover_wheels"/>
            </visual>
            <collision>
                <geometry>
                    <cylinder radius="${wheel_radius}" length="${wheel_length}"/>
                </geometry>
            </collision>
            <inertial>
                <mass value="${wheel_mass}"/>
                <inertia ixx="0.0027" ixy="0.0" ixz="0.0" iyy="0.0027" iyz="0.0" izz="0.005"/>
            </inertial>
        </link>
    </xacro:macro>

    <xacro:rover_wheel prefix="front_left" x_reflect="1" y_reflect="1"/>
    <xacro:rover_wheel prefix="front_right" x_reflect="1" y_reflect="-1"/>
    <xacro:rover_wheel prefix="rear_left" x_reflect="-1" y_reflect="1"/>
    <xacro:rover_wheel prefix="rear_right" x_reflect="-1" y_reflect="-1"/>

    <gazebo>
        <plugin filename="ignition-gazebo-diff-drive-system" name="ignition::gazebo::systems::DiffDrive">
            <left_joint>front_left_wheel_joint</left_joint>
            <left_joint>rear_left_wheel_joint</left_joint>
            <right_joint>front_right_wheel_joint</right_joint>
            <right_joint>rear_right_wheel_joint</right_joint>
            <wheel_separation>0.35</wheel_separation>
            <wheel_radius>0.1</wheel_radius>
            <odom_publish_frequency>50</odom_publish_frequency>
            <topic>cmd_vel</topic>
        </plugin>
    </gazebo>

</robot>
